Workbook

Sheet Petunjuk
B1: Eksperimen Harga: 15 barang × 5 toko (Kudus)
B2: Tujuan: membuktikan apakah selisih harga antar toko cukup besar untuk membuat rekomendasi 'beli di mana' bermakna (lihat kriteria pivot di PLAN.md).
B4: Cara mengisi
B5: 1. Isi sheet 'Catat': nama, tipe, dan tanggal cek tiap toko (sel kuning di baris 4–6).
B6: 2. Catat harga rak yang berlaku untuk SEMUA pembeli, per kemasan, dalam angka saja (tanpa 'Rp', titik, atau tanda '-').
B7: 3. Barang harus PERSIS sama di semua toko: merek, varian, dan ukuran. Kalau ukuran di rak berbeda dari kolom 'Kemasan', ubah teks kemasan itu agar sama di semua toko.
B8: 4. Kalau toko tidak menjual barangnya, kosongkan selnya. Jangan isi 0 atau teks.
B9: 5. Harga khusus member/kartu atau 'beli 2 gratis 1' tidak dimasukkan ke kolom harga; tulis di kolom Catatan.
B10: 6. Cek semua toko dalam 1–2 hari yang sama (harga berubah mingguan). Foto label rak sebagai bukti; foto ini juga berguna sebagai bahan uji fitur label rak nanti.
B11: 7. Lihat sheet 'Ringkasan'. Hasilnya menentukan apakah wedge produk dilanjutkan (lihat vonis di sana).
B13: Legenda warna
B14: Kuning + teks biru | C14: Sel yang kamu isi
B15: Abu-abu, teks hitam | C15: Rumus, jangan diubah
B18: Contoh format pengisian (angka contoh, BUKAN data nyata)
B19: Barang | C19: Kemasan | D19: Toko 1 | E19: Toko 2 | F19: Toko 3 | G19: Toko 4 | H19: Toko 5 | I19: Catatan
B20: Indomie Goreng | C20: 1 bungkus (85 g) | D20: 3500 | E20: 3300 | F20: 3400 | H20: 3200 | I20: Toko 4 tidak menjual
B22: Asumsi dalam ringkasan: biaya tetap per toko tambahan, ambang selisih bermakna, dan minimum barang lengkap diatur di sheet 'Ringkasan' (sel biru).

Sheet Catat
A1: Catat harga (Rp per kemasan)
A2: Isi hanya sel kuning. Kosongkan jika toko tidak menjual. Baca sheet 'Petunjuk' dulu.
B4: Nama toko → | D4: Toko 1 | E4: Toko 2 | F4: Toko 3 | G4: Toko 4 | H4: Toko 5
B5: Tipe toko →
B6: Tanggal cek →
A7: No | B7: Barang | C7: Kemasan | D7: =D4 | E7: =E4 | F7: =F4 | G7: =G4 | H7: =H4 | I7: Termurah (Rp) | J7: Toko termurah | K7: Selisih maks–min (Rp) | L7: Selisih (%) | M7: Ada di semua toko? (1/0) | N7: Catatan (promo, member, dsb.)
A8: 1 | B8: Beras premium (pilih 1 merek yang sama di semua toko) | C8: 5 kg | I8: =IF(COUNT(D8:H8)=0,"",MIN(D8:H8)) | J8: =IF(COUNT(D8:H8)=0,"",INDEX($D$4:$H$4,MATCH(I8,D8:H8,0))) | K8: =IF(COUNT(D8:H8)<2,"",MAX(D8:H8)-MIN(D8:H8)) | L8: =IF(COUNT(D8:H8)<2,"",IF(MIN(D8:H8)=0,"",(MAX(D8:H8)-MIN(D8:H8))/MIN(D8:H8))) | M8: =IF(COUNT(D8:H8)=COLUMNS(D8:H8),1,0)
A9: 2 | B9: Minyak goreng kemasan (mis. Bimoli / Sania) | C9: 2 L | I9: =IF(COUNT(D9:H9)=0,"",MIN(D9:H9)) | J9: =IF(COUNT(D9:H9)=0,"",INDEX($D$4:$H$4,MATCH(I9,D9:H9,0))) | K9: =IF(COUNT(D9:H9)<2,"",MAX(D9:H9)-MIN(D9:H9)) | L9: =IF(COUNT(D9:H9)<2,"",IF(MIN(D9:H9)=0,"",(MAX(D9:H9)-MIN(D9:H9))/MIN(D9:H9))) | M9: =IF(COUNT(D9:H9)=COLUMNS(D9:H9),1,0)
A10: 3 | B10: Minyakita (harga eceran tertinggi, sebagai pembanding) | C10: 1 L | I10: =IF(COUNT(D10:H10)=0,"",MIN(D10:H10)) | J10: =IF(COUNT(D10:H10)=0,"",INDEX($D$4:$H$4,MATCH(I10,D10:H10,0))) | K10: =IF(COUNT(D10:H10)<2,"",MAX(D10:H10)-MIN(D10:H10)) | L10: =IF(COUNT(D10:H10)<2,"",IF(MIN(D10:H10)=0,"",(MAX(D10:H10)-MIN(D10:H10))/MIN(D10:H10))) | M10: =IF(COUNT(D10:H10)=COLUMNS(D10:H10),1,0)
A11: 4 | B11: Gula pasir (mis. Gulaku) | C11: 1 kg | I11: =IF(COUNT(D11:H11)=0,"",MIN(D11:H11)) | J11: =IF(COUNT(D11:H11)=0,"",INDEX($D$4:$H$4,MATCH(I11,D11:H11,0))) | K11: =IF(COUNT(D11:H11)<2,"",MAX(D11:H11)-MIN(D11:H11)) | L11: =IF(COUNT(D11:H11)<2,"",IF(MIN(D11:H11)=0,"",(MAX(D11:H11)-MIN(D11:H11))/MIN(D11:H11))) | M11: =IF(COUNT(D11:H11)=COLUMNS(D11:H11),1,0)
A12: 5 | B12: Telur ayam ras | C12: 1 kg | I12: =IF(COUNT(D12:H12)=0,"",MIN(D12:H12)) | J12: =IF(COUNT(D12:H12)=0,"",INDEX($D$4:$H$4,MATCH(I12,D12:H12,0))) | K12: =IF(COUNT(D12:H12)<2,"",MAX(D12:H12)-MIN(D12:H12)) | L12: =IF(COUNT(D12:H12)<2,"",IF(MIN(D12:H12)=0,"",(MAX(D12:H12)-MIN(D12:H12))/MIN(D12:H12))) | M12: =IF(COUNT(D12:H12)=COLUMNS(D12:H12),1,0)
A13: 6 | B13: Tepung terigu Segitiga Biru | C13: 1 kg | I13: =IF(COUNT(D13:H13)=0,"",MIN(D13:H13)) | J13: =IF(COUNT(D13:H13)=0,"",INDEX($D$4:$H$4,MATCH(I13,D13:H13,0))) | K13: =IF(COUNT(D13:H13)<2,"",MAX(D13:H13)-MIN(D13:H13)) | L13: =IF(COUNT(D13:H13)<2,"",IF(MIN(D13:H13)=0,"",(MAX(D13:H13)-MIN(D13:H13))/MIN(D13:H13))) | M13: =IF(COUNT(D13:H13)=COLUMNS(D13:H13),1,0)
A14: 7 | B14: Indomie Goreng | C14: 1 bungkus (85 g) | I14: =IF(COUNT(D14:H14)=0,"",MIN(D14:H14)) | J14: =IF(COUNT(D14:H14)=0,"",INDEX($D$4:$H$4,MATCH(I14,D14:H14,0))) | K14: =IF(COUNT(D14:H14)<2,"",MAX(D14:H14)-MIN(D14:H14)) | L14: =IF(COUNT(D14:H14)<2,"",IF(MIN(D14:H14)=0,"",(MAX(D14:H14)-MIN(D14:H14))/MIN(D14:H14))) | M14: =IF(COUNT(D14:H14)=COLUMNS(D14:H14),1,0)
A15: 8 | B15: Susu UHT Ultra Milk Full Cream | C15: 1 L | I15: =IF(COUNT(D15:H15)=0,"",MIN(D15:H15)) | J15: =IF(COUNT(D15:H15)=0,"",INDEX($D$4:$H$4,MATCH(I15,D15:H15,0))) | K15: =IF(COUNT(D15:H15)<2,"",MAX(D15:H15)-MIN(D15:H15)) | L15: =IF(COUNT(D15:H15)<2,"",IF(MIN(D15:H15)=0,"",(MAX(D15:H15)-MIN(D15:H15))/MIN(D15:H15))) | M15: =IF(COUNT(D15:H15)=COLUMNS(D15:H15),1,0)
A16: 9 | B16: Susu kental manis Frisian Flag | C16: 370 g | I16: =IF(COUNT(D16:H16)=0,"",MIN(D16:H16)) | J16: =IF(COUNT(D16:H16)=0,"",INDEX($D$4:$H$4,MATCH(I16,D16:H16,0))) | K16: =IF(COUNT(D16:H16)<2,"",MAX(D16:H16)-MIN(D16:H16)) | L16: =IF(COUNT(D16:H16)<2,"",IF(MIN(D16:H16)=0,"",(MAX(D16:H16)-MIN(D16:H16))/MIN(D16:H16))) | M16: =IF(COUNT(D16:H16)=COLUMNS(D16:H16),1,0)
A17: 10 | B17: Kopi bubuk Kapal Api Special | C17: 165 g | I17: =IF(COUNT(D17:H17)=0,"",MIN(D17:H17)) | J17: =IF(COUNT(D17:H17)=0,"",INDEX($D$4:$H$4,MATCH(I17,D17:H17,0))) | K17: =IF(COUNT(D17:H17)<2,"",MAX(D17:H17)-MIN(D17:H17)) | L17: =IF(COUNT(D17:H17)<2,"",IF(MIN(D17:H17)=0,"",(MAX(D17:H17)-MIN(D17:H17))/MIN(D17:H17))) | M17: =IF(COUNT(D17:H17)=COLUMNS(D17:H17),1,0)
A18: 11 | B18: Teh celup Sariwangi | C18: 25 kantong | I18: =IF(COUNT(D18:H18)=0,"",MIN(D18:H18)) | J18: =IF(COUNT(D18:H18)=0,"",INDEX($D$4:$H$4,MATCH(I18,D18:H18,0))) | K18: =IF(COUNT(D18:H18)<2,"",MAX(D18:H18)-MIN(D18:H18)) | L18: =IF(COUNT(D18:H18)<2,"",IF(MIN(D18:H18)=0,"",(MAX(D18:H18)-MIN(D18:H18))/MIN(D18:H18))) | M18: =IF(COUNT(D18:H18)=COLUMNS(D18:H18),1,0)
A19: 12 | B19: Kecap manis ABC | C19: 275 ml | I19: =IF(COUNT(D19:H19)=0,"",MIN(D19:H19)) | J19: =IF(COUNT(D19:H19)=0,"",INDEX($D$4:$H$4,MATCH(I19,D19:H19,0))) | K19: =IF(COUNT(D19:H19)<2,"",MAX(D19:H19)-MIN(D19:H19)) | L19: =IF(COUNT(D19:H19)<2,"",IF(MIN(D19:H19)=0,"",(MAX(D19:H19)-MIN(D19:H19))/MIN(D19:H19))) | M19: =IF(COUNT(D19:H19)=COLUMNS(D19:H19),1,0)
... A22: 15 | B22: Sabun cuci piring Sunlight (pouch) | C22: catat ukuran persis | I22: =IF(COUNT(D22:H22)=0,"",MIN(D22:H22)) | J22: =IF(COUNT(D22:H22)=0,"",INDEX($D$4:$H$4,MATCH(I22,D22:H22,0))) | K22: =IF(COUNT(D22:H22)<2,"",MAX(D22:H22)-MIN(D22:H22)) | L22: =IF(COUNT(D22:H22)<2,"",IF(MIN(D22:H22)=0,"",(MAX(D22:H22)-MIN(D22:H22))/MIN(D22:H22))) | M22: =IF(COUNT(D22:H22)=COLUMNS(D22:H22),1,0)

Sheet Ringkasan
B1: Ringkasan eksperimen harga
B2: Hanya barang yang tercatat di SEMUA toko dipakai agar perbandingan adil.
B4: Asumsi (sel biru, boleh diubah)
B5: Biaya tetap per toko tambahan (Rp) | C5: 3000 | D5: Asumsi dari PLAN.md; pengganti jarak/bensin/waktu.
B6: Ambang selisih bermakna (%) | C6: 0.03 | D6: Kriteria pivot PLAN.md: di bawah 3% dianggap kecil.
B7: Minimum barang lengkap agar vonis dipercaya | C7: 8 | D7: Asumsi kerja (belum dari sumber lain): 8 dari 15 barang.
B9: Kelengkapan data
B10: Barang tercatat di semua toko | C10: =SUM(Catat!$M$8:$M$22)
B11: Total barang dalam daftar | C11: =COUNTA(Catat!$B$8:$B$22)
B13: Total keranjang per toko (barang lengkap saja)
B14: Toko | C14: Total (Rp) | D14: Lebih mahal dari toko termurah (Rp) | E14: Lebih mahal (%)
B15: =Catat!D4 | C15: =SUMIFS(Catat!D8:D22,Catat!$M$8:$M$22,1) | D15: =C15-MIN($C$15:$C$19) | E15: =IF(MIN($C$15:$C$19)=0,"",D15/MIN($C$15:$C$19))
B16: =Catat!E4 | C16: =SUMIFS(Catat!E8:E22,Catat!$M$8:$M$22,1) | D16: =C16-MIN($C$15:$C$19) | E16: =IF(MIN($C$15:$C$19)=0,"",D16/MIN($C$15:$C$19))
B17: =Catat!F4 | C17: =SUMIFS(Catat!F8:F22,Catat!$M$8:$M$22,1) | D17: =C17-MIN($C$15:$C$19) | E17: =IF(MIN($C$15:$C$19)=0,"",D17/MIN($C$15:$C$19))
B18: =Catat!G4 | C18: =SUMIFS(Catat!G8:G22,Catat!$M$8:$M$22,1) | D18: =C18-MIN($C$15:$C$19) | E18: =IF(MIN($C$15:$C$19)=0,"",D18/MIN($C$15:$C$19))
B19: =Catat!H4 | C19: =SUMIFS(Catat!H8:H22,Catat!$M$8:$M$22,1) | D19: =C19-MIN($C$15:$C$19) | E19: =IF(MIN($C$15:$C$19)=0,"",D19/MIN($C$15:$C$19))
B21: Beli tiap barang di toko termurah (batas atas, butuh ke semua toko)
B22: Total jika semua barang di toko termurahnya | C22: =SUMIFS(Catat!$I$8:$I$22,Catat!$M$8:$M$22,1)
B23: Hemat vs toko tunggal termurah (Rp) | C23: =MIN($C$15:$C$19)-C22
B24: Hemat vs toko tunggal termurah (%) | C24: =IF(MIN($C$15:$C$19)=0,"",C23/MIN($C$15:$C$19))
B26: Kombinasi 2 toko (tiap barang dibeli di yang lebih murah dari keduanya)
B27: Kombinasi | C27: Total (Rp) | D27: Hemat kotor vs toko tunggal termurah (Rp) | E27: Hemat bersih setelah biaya toko tambahan (Rp) | F27: Hemat bersih (%)
B28: =Catat!D4&" + "&Catat!E4 | C28: =SUMPRODUCT(Catat!$M$8:$M$22*((Catat!$D$8:$D$22<Catat!$E$8:$E$22)*Catat!$D$8:$D$22+(Catat!$D$8:$D$22>=Catat!$E$8:$E$22)*Catat!$E$8:$E$22)) | D28: =MIN($C$15:$C$19)-C28 | E28: =D28-$C$5 | F28: =IF(MIN($C$15:$C$19)=0,"",E28/MIN($C$15:$C$19))
B29: =Catat!D4&" + "&Catat!F4 | C29: =SUMPRODUCT(Catat!$M$8:$M$22*((Catat!$D$8:$D$22<Catat!$F$8:$F$22)*Catat!$D$8:$D$22+(Catat!$D$8:$D$22>=Catat!$F$8:$F$22)*Catat!$F$8:$F$22)) | D29: =MIN($C$15:$C$19)-C29 | E29: =D29-$C$5 | F29: =IF(MIN($C$15:$C$19)=0,"",E29/MIN($C$15:$C$19))
B30: =Catat!D4&" + "&Catat!G4 | C30: =SUMPRODUCT(Catat!$M$8:$M$22*((Catat!$D$8:$D$22<Catat!$G$8:$G$22)*Catat!$D$8:$D$22+(Catat!$D$8:$D$22>=Catat!$G$8:$G$22)*Catat!$G$8:$G$22)) | D30: =MIN($C$15:$C$19)-C30 | E30: =D30-$C$5 | F30: =IF(MIN($C$15:$C$19)=0,"",E30/MIN($C$15:$C$19))
B31: =Catat!D4&" + "&Catat!H4 | C31: =SUMPRODUCT(Catat!$M$8:$M$22*((Catat!$D$8:$D$22<Catat!$H$8:$H$22)*Catat!$D$8:$D$22+(Catat!$D$8:$D$22>=Catat!$H$8:$H$22)*Catat!$H$8:$H$22)) | D31: =MIN($C$15:$C$19)-C31 | E31: =D31-$C$5 | F31: =IF(MIN($C$15:$C$19)=0,"",E31/MIN($C$15:$C$19))
B32: =Catat!E4&" + "&Catat!F4 | C32: =SUMPRODUCT(Catat!$M$8:$M$22*((Catat!$E$8:$E$22<Catat!$F$8:$F$22)*Catat!$E$8:$E$22+(Catat!$E$8:$E$22>=Catat!$F$8:$F$22)*Catat!$F$8:$F$22)) | D32: =MIN($C$15:$C$19)-C32 | E32: =D32-$C$5 | F32: =IF(MIN($C$15:$C$19)=0,"",E32/MIN($C$15:$C$19))
B33: =Catat!E4&" + "&Catat!G4 | C33: =SUMPRODUCT(Catat!$M$8:$M$22*((Catat!$E$8:$E$22<Catat!$G$8:$G$22)*Catat!$E$8:$E$22+(Catat!$E$8:$E$22>=Catat!$G$8:$G$22)*Catat!$G$8:$G$22)) | D33: =MIN($C$15:$C$19)-C33 | E33: =D33-$C$5 | F33: =IF(MIN($C$15:$C$19)=0,"",E33/MIN($C$15:$C$19))
B34: =Catat!E4&" + "&Catat!H4 | C34: =SUMPRODUCT(Catat!$M$8:$M$22*((Catat!$E$8:$E$22<Catat!$H$8:$H$22)*Catat!$E$8:$E$22+(Catat!$E$8:$E$22>=Catat!$H$8:$H$22)*Catat!$H$8:$H$22)) | D34: =MIN($C$15:$C$19)-C34 | E34: =D34-$C$5 | F34: =IF(MIN($C$15:$C$19)=0,"",E34/MIN($C$15:$C$19))
B35: =Catat!F4&" + "&Catat!G4 | C35: =SUMPRODUCT(Catat!$M$8:$M$22*((Catat!$F$8:$F$22<Catat!$G$8:$G$22)*Catat!$F$8:$F$22+(Catat!$F$8:$F$22>=Catat!$G$8:$G$22)*Catat!$G$8:$G$22)) | D35: =MIN($C$15:$C$19)-C35 | E35: =D35-$C$5 | F35: =IF(MIN($C$15:$C$19)=0,"",E35/MIN($C$15:$C$19))
B36: =Catat!F4&" + "&Catat!H4 | C36: =SUMPRODUCT(Catat!$M$8:$M$22*((Catat!$F$8:$F$22<Catat!$H$8:$H$22)*Catat!$F$8:$F$22+(Catat!$F$8:$F$22>=Catat!$H$8:$H$22)*Catat!$H$8:$H$22)) | D36: =MIN($C$15:$C$19)-C36 | E36: =D36-$C$5 | F36: =IF(MIN($C$15:$C$19)=0,"",E36/MIN($C$15:$C$19))
B37: =Catat!G4&" + "&Catat!H4 | C37: =SUMPRODUCT(Catat!$M$8:$M$22*((Catat!$G$8:$G$22<Catat!$H$8:$H$22)*Catat!$G$8:$G$22+(Catat!$G$8:$G$22>=Catat!$H$8:$H$22)*Catat!$H$8:$H$22)) | D37: =MIN($C$15:$C$19)-C37 | E37: =D37-$C$5 | F37: =IF(MIN($C$15:$C$19)=0,"",E37/MIN($C$15:$C$19))
B38: Kombinasi 2 toko terbaik (hemat bersih tertinggi) | C38: =IF(MAX(E28:E37)<=0,"tidak ada yang untung",INDEX(B28:B37,MATCH(MAX(E28:E37),E28:E37,0)))
B39: Hemat bersih terbaik 2 toko (Rp) | C39: =MAX(E28:E37)
B40: Hemat bersih terbaik 2 toko (%) | C40: =MAX(F28:F37)
B42: Sebaran selisih harga per barang (semua barang yang tercatat di ≥ 2 toko)
B43: Jumlah barang dengan selisih ≥ ambang | C43: =COUNTIF(Catat!$L$8:$L$22,">="&$C$6)
B44: Median selisih maks–min (%) | C44: =IFERROR(MEDIAN(Catat!$L$8:$L$22),"")
B45: Selisih terbesar (%) | C45: =IF(COUNT(Catat!$L$8:$L$22)=0,"",MAX(Catat!$L$8:$L$22))
B47: Vonis
...
